Workbook

Sheet Depressed
A1: word_1 | B1: word_2 | C1: Depressed | D1: Not_depressed | E1: All
A2: brown | B2: anger | C2: =('depressed breakdown 0-7'!A2+'depressed breakdown 0-7'!B2+'depressed breakdown 0-7'!C2+'depressed breakdown 0-7'!D2+'depressed breakdown 0-7'!E2+'depressed breakdown 0-7'!F2+'depressed breakdown 0-7'!G2+'depressed breakdown 0-7'!H2+'depressed breakdown 0-7'!I2+'depressed breakdown 0-7'!J2+'depressed breakdown 0-7'!K2+'depressed breakdown 0-7'!L2+'depressed breakdown 0-7'!M2+'depressed breakdown 0-7'!N2+'depressed breakdown 0-7'!O2+'depressed breakdown 0-7'!P2+'depressed breakdown 0-7'!Q2+'depressed breakdown 0-7'!R2)/18 -> 1.3888889 | D2: =('not depressed breakdwon 0-7'!D2+'not depressed breakdwon 0-7'!E2+'not depressed breakdwon 0-7'!F2+'not depressed breakdwon 0-7'!G2+'not depressed breakdwon 0-7'!I2+'not depressed breakdwon 0-7'!J2+'not depressed breakdwon 0-7'!K2+'not depressed breakdwon 0-7'!N2+'not depressed breakdwon 0-7'!O2+'not depressed breakdwon 0-7'!P2+'not depressed breakdwon 0-7'!Q2+'not depressed breakdwon 0-7'!R2+'not depressed breakdwon 0-7'!S2+'not depressed breakdwon 0-7'!T2+'not depressed breakdwon 0-7'!U2+'not depressed breakdwon 0-7'!W2+'not depressed breakdwon 0-7'!X2+'not depressed breakdwon 0-7'!Z2+'not depressed breakdwon 0-7'!AA2+'not depressed breakdwon 0-7'!AB2+'not depressed breakdwon 0-7'!AC2+'not depressed breakdwon 0-7'!AD2+'not depressed breakdwon 0-7'!AE2+'not depressed breakdwon 0-7'!AF2+'not depressed breakdwon 0-7'!AG2+'not depressed breakdwon 0-7'!AI2+'not depressed breakdwon 0-7'!AJ2+'not depressed breakdwon 0-7'!AK2+'not depressed breakdwon 0-7'!AL2+'not depressed breakdwon 0-7'!AO2+'not depressed breakdwon 0-7'!AP2+'not depressed breakdwon 0-7'!AR2+'not depressed breakdwon 0-7'!AS2+'not depressed breakdwon 0-7'!AT2+'not depressed breakdwon 0-7'!AU2+'not depressed breakdwon 0-7'!AV2+'not depressed breakdwon 0-7'!AW2)/37 -> 1.2702703 | E2: 1.1583333
A3: orange | B3: anxiety | C3: =('depressed breakdown 0-7'!A3+'depressed breakdown 0-7'!B3+'depressed breakdown 0-7'!C3+'depressed breakdown 0-7'!D3+'depressed breakdown 0-7'!E3+'depressed breakdown 0-7'!F3+'depressed breakdown 0-7'!G3+'depressed breakdown 0-7'!H3+'depressed breakdown 0-7'!I3+'depressed breakdown 0-7'!J3+'depressed breakdown 0-7'!K3+'depressed breakdown 0-7'!L3+'depressed breakdown 0-7'!M3+'depressed breakdown 0-7'!N3+'depressed breakdown 0-7'!O3+'depressed breakdown 0-7'!P3+'depressed breakdown 0-7'!Q3+'depressed breakdown 0-7'!R3)/18 -> 0.83333333 | D3: =('not depressed breakdwon 0-7'!D3+'not depressed breakdwon 0-7'!E3+'not depressed breakdwon 0-7'!F3+'not depressed breakdwon 0-7'!G3+'not depressed breakdwon 0-7'!I3+'not depressed breakdwon 0-7'!J3+'not depressed breakdwon 0-7'!K3+'not depressed breakdwon 0-7'!N3+'not depressed breakdwon 0-7'!O3+'not depressed breakdwon 0-7'!P3+'not depressed breakdwon 0-7'!Q3+'not depressed breakdwon 0-7'!R3+'not depressed breakdwon 0-7'!S3+'not depressed breakdwon 0-7'!T3+'not depressed breakdwon 0-7'!U3+'not depressed breakdwon 0-7'!W3+'not depressed breakdwon 0-7'!X3+'not depressed breakdwon 0-7'!Z3+'not depressed breakdwon 0-7'!AA3+'not depressed breakdwon 0-7'!AB3+'not depressed breakdwon 0-7'!AC3+'not depressed breakdwon 0-7'!AD3+'not depressed breakdwon 0-7'!AE3+'not depressed breakdwon 0-7'!AF3+'not depressed breakdwon 0-7'!AG3+'not depressed breakdwon 0-7'!AI3+'not depressed breakdwon 0-7'!AJ3+'not depressed breakdwon 0-7'!AK3+'not depressed breakdwon 0-7'!AL3+'not depressed breakdwon 0-7'!AO3+'not depressed breakdwon 0-7'!AP3+'not depressed breakdwon 0-7'!AR3+'not depressed breakdwon 0-7'!AS3+'not depressed breakdwon 0-7'!AT3+'not depressed breakdwon 0-7'!AU3+'not depressed breakdwon 0-7'!AV3+'not depressed breakdwon 0-7'!AW3)/37 -> 1.5945946 | E3: 1.55
A4: red | B4: yellow | C4: =('depressed breakdown 0-7'!A4+'depressed breakdown 0-7'!B4+'depressed breakdown 0-7'!C4+'depressed breakdown 0-7'!D4+'depressed breakdown 0-7'!E4+'depressed breakdown 0-7'!F4+'depressed breakdown 0-7'!G4+'depressed breakdown 0-7'!H4+'depressed breakdown 0-7'!I4+'depressed breakdown 0-7'!J4+'depressed breakdown 0-7'!K4+'depressed breakdown 0-7'!L4+'depressed breakdown 0-7'!M4+'depressed breakdown 0-7'!N4+'depressed breakdown 0-7'!O4+'depressed breakdown 0-7'!P4+'depressed breakdown 0-7'!Q4+'depressed breakdown 0-7'!R4)/18 -> 3.6111111 | D4: =('not depressed breakdwon 0-7'!D4+'not depressed breakdwon 0-7'!E4+'not depressed breakdwon 0-7'!F4+'not depressed breakdwon 0-7'!G4+'not depressed breakdwon 0-7'!I4+'not depressed breakdwon 0-7'!J4+'not depressed breakdwon 0-7'!K4+'not depressed breakdwon 0-7'!N4+'not depressed breakdwon 0-7'!O4+'not depressed breakdwon 0-7'!P4+'not depressed breakdwon 0-7'!Q4+'not depressed breakdwon 0-7'!R4+'not depressed breakdwon 0-7'!S4+'not depressed breakdwon 0-7'!T4+'not depressed breakdwon 0-7'!U4+'not depressed breakdwon 0-7'!W4+'not depressed breakdwon 0-7'!X4+'not depressed breakdwon 0-7'!Z4+'not depressed breakdwon 0-7'!AA4+'not depressed breakdwon 0-7'!AB4+'not depressed breakdwon 0-7'!AC4+'not depressed breakdwon 0-7'!AD4+'not depressed breakdwon 0-7'!AE4+'not depressed breakdwon 0-7'!AF4+'not depressed breakdwon 0-7'!AG4+'not depressed breakdwon 0-7'!AI4+'not depressed breakdwon 0-7'!AJ4+'not depressed breakdwon 0-7'!AK4+'not depressed breakdwon 0-7'!AL4+'not depressed breakdwon 0-7'!AO4+'not depressed breakdwon 0-7'!AP4+'not depressed breakdwon 0-7'!AR4+'not depressed breakdwon 0-7'!AS4+'not depressed breakdwon 0-7'!AT4+'not depressed breakdwon 0-7'!AU4+'not depressed breakdwon 0-7'!AV4+'not depressed breakdwon 0-7'!AW4)/37 -> 3.4594595 | E4: 3.875
A5: black | B5: blue | C5: =('depressed breakdown 0-7'!A5+'depressed breakdown 0-7'!B5+'depressed breakdown 0-7'!C5+'depressed breakdown 0-7'!D5+'depressed breakdown 0-7'!E5+'depressed breakdown 0-7'!F5+'depressed breakdown 0-7'!G5+'depressed breakdown 0-7'!H5+'depressed breakdown 0-7'!I5+'depressed breakdown 0-7'!J5+'depressed breakdown 0-7'!K5+'depressed breakdown 0-7'!L5+'depressed breakdown 0-7'!M5+'depressed breakdown 0-7'!N5+'depressed breakdown 0-7'!O5+'depressed breakdown 0-7'!P5+'depressed breakdown 0-7'!Q5+'depressed breakdown 0-7'!R5)/18 -> 4.5555556 | D5: =('not depressed breakdwon 0-7'!D5+'not depressed breakdwon 0-7'!E5+'not depressed breakdwon 0-7'!F5+'not depressed breakdwon 0-7'!G5+'not depressed breakdwon 0-7'!I5+'not depressed breakdwon 0-7'!J5+'not depressed breakdwon 0-7'!K5+'not depressed breakdwon 0-7'!N5+'not depressed breakdwon 0-7'!O5+'not depressed breakdwon 0-7'!P5+'not depressed breakdwon 0-7'!Q5+'not depressed breakdwon 0-7'!R5+'not depressed breakdwon 0-7'!S5+'not depressed breakdwon 0-7'!T5+'not depressed breakdwon 0-7'!U5+'not depressed breakdwon 0-7'!W5+'not depressed breakdwon 0-7'!X5+'not depressed breakdwon 0-7'!Z5+'not depressed breakdwon 0-7'!AA5+'not depressed breakdwon 0-7'!AB5+'not depressed breakdwon 0-7'!AC5+'not depressed breakdwon 0-7'!AD5+'not depressed breakdwon 0-7'!AE5+'not depressed breakdwon 0-7'!AF5+'not depressed breakdwon 0-7'!AG5+'not depressed breakdwon 0-7'!AI5+'not depressed breakdwon 0-7'!AJ5+'not depressed breakdwon 0-7'!AK5+'not depressed breakdwon 0-7'!AL5+'not depressed breakdwon 0-7'!AO5+'not depressed breakdwon 0-7'!AP5+'not depressed breakdwon 0-7'!AR5+'not depressed breakdwon 0-7'!AS5+'not depressed breakdwon 0-7'!AT5+'not depressed breakdwon 0-7'!AU5+'not depressed breakdwon 0-7'!AV5+'not depressed breakdwon 0-7'!AW5)/37 -> 3.7837838 | E5: 4.4583333
A6: green | B6: calm | C6: =('depressed breakdown 0-7'!A6+'depressed breakdown 0-7'!B6+'depressed breakdown 0-7'!C6+'depressed breakdown 0-7'!D6+'depressed breakdown 0-7'!E6+'depressed breakdown 0-7'!F6+'depressed breakdown 0-7'!G6+'depressed breakdown 0-7'!H6+'depressed breakdown 0-7'!I6+'depressed breakdown 0-7'!J6+'depressed breakdown 0-7'!K6+'depressed breakdown 0-7'!L6+'depressed breakdown 0-7'!M6+'depressed breakdown 0-7'!N6+'depressed breakdown 0-7'!O6+'depressed breakdown 0-7'!P6+'depressed breakdown 0-7'!Q6+'depressed breakdown 0-7'!R6)/18 -> 4.1111111 | D6: =('not depressed breakdwon 0-7'!D6+'not depressed breakdwon 0-7'!E6+'not depressed breakdwon 0-7'!F6+'not depressed breakdwon 0-7'!G6+'not depressed breakdwon 0-7'!I6+'not depressed breakdwon 0-7'!J6+'not depressed breakdwon 0-7'!K6+'not depressed breakdwon 0-7'!N6+'not depressed breakdwon 0-7'!O6+'not depressed breakdwon 0-7'!P6+'not depressed breakdwon 0-7'!Q6+'not depressed breakdwon 0-7'!R6+'not depressed breakdwon 0-7'!S6+'not depressed breakdwon 0-7'!T6+'not depressed breakdwon 0-7'!U6+'not depressed breakdwon 0-7'!W6+'not depressed breakdwon 0-7'!X6+'not depressed breakdwon 0-7'!Z6+'not depressed breakdwon 0-7'!AA6+'not depressed breakdwon 0-7'!AB6+'not depressed breakdwon 0-7'!AC6+'not depressed breakdwon 0-7'!AD6+'not depressed breakdwon 0-7'!AE6+'not depressed breakdwon 0-7'!AF6+'not depressed breakdwon 0-7'!AG6+'not depressed breakdwon 0-7'!AI6+'not depressed breakdwon 0-7'!AJ6+'not depressed breakdwon 0-7'!AK6+'not depressed breakdwon 0-7'!AL6+'not depressed breakdwon 0-7'!AO6+'not depressed breakdwon 0-7'!AP6+'not depressed breakdwon 0-7'!AR6+'not depressed breakdwon 0-7'!AS6+'not depressed breakdwon 0-7'!AT6+'not depressed breakdwon 0-7'!AU6+'not depressed breakdwon 0-7'!AV6+'not depressed breakdwon 0-7'!AW6)/37 -> 3.3513514 | E6: 3.4666667
A7: red | B7: pink | C7: =('depressed breakdown 0-7'!A7+'depressed breakdown 0-7'!B7+'depressed breakdown 0-7'!C7+'depressed breakdown 0-7'!D7+'depressed breakdown 0-7'!E7+'depressed breakdown 0-7'!F7+'depressed breakdown 0-7'!G7+'depressed breakdown 0-7'!H7+'depressed breakdown 0-7'!I7+'depressed breakdown 0-7'!J7+'depressed breakdown 0-7'!K7+'depressed breakdown 0-7'!L7+'depressed breakdown 0-7'!M7+'depressed breakdown 0-7'!N7+'depressed breakdown 0-7'!O7+'depressed breakdown 0-7'!P7+'depressed breakdown 0-7'!Q7+'depressed breakdown 0-7'!R7)/18 -> 5.0555556 | D7: =('not depressed breakdwon 0-7'!D7+'not depressed breakdwon 0-7'!E7+'not depressed breakdwon 0-7'!F7+'not depressed breakdwon 0-7'!G7+'not depressed breakdwon 0-7'!I7+'not depressed breakdwon 0-7'!J7+'not depressed breakdwon 0-7'!K7+'not depressed breakdwon 0-7'!N7+'not depressed breakdwon 0-7'!O7+'not depressed breakdwon 0-7'!P7+'not depressed breakdwon 0-7'!Q7+'not depressed breakdwon 0-7'!R7+'not depressed breakdwon 0-7'!S7+'not depressed breakdwon 0-7'!T7+'not depressed breakdwon 0-7'!U7+'not depressed breakdwon 0-7'!W7+'not depressed breakdwon 0-7'!X7+'not depressed breakdwon 0-7'!Z7+'not depressed breakdwon 0-7'!AA7+'not depressed breakdwon 0-7'!AB7+'not depressed breakdwon 0-7'!AC7+'not depressed breakdwon 0-7'!AD7+'not depressed breakdwon 0-7'!AE7+'not depressed breakdwon 0-7'!AF7+'not depressed breakdwon 0-7'!AG7+'not depressed breakdwon 0-7'!AI7+'not depressed breakdwon 0-7'!AJ7+'not depressed breakdwon 0-7'!AK7+'not depressed breakdwon 0-7'!AL7+'not depressed breakdwon 0-7'!AO7+'not depressed breakdwon 0-7'!AP7+'not depressed breakdwon 0-7'!AR7+'not depressed breakdwon 0-7'!AS7+'not depressed breakdwon 0-7'!AT7+'not depressed breakdwon 0-7'!AU7+'not depressed breakdwon 0-7'!AV7+'not depressed breakdwon 0-7'!AW7)/37 -> 5 | E7: 5.2416667
A8: envy | B8: joy | C8: =('depressed breakdown 0-7'!A8+'depressed breakdown 0-7'!B8+'depressed breakdown 0-7'!C8+'depressed breakdown 0-7'!D8+'depressed breakdown 0-7'!E8+'depressed breakdown 0-7'!F8+'depressed breakdown 0-7'!G8+'depressed breakdown 0-7'!H8+'depressed breakdown 0-7'!I8+'depressed breakdown 0-7'!J8+'depressed breakdown 0-7'!K8+'depressed breakdown 0-7'!L8+'depressed breakdown 0-7'!M8+'depressed breakdown 0-7'!N8+'depressed breakdown 0-7'!O8+'depressed breakdown 0-7'!P8+'depressed breakdown 0-7'!Q8+'depressed breakdown 0-7'!R8)/18 -> 1.9444444 | D8: =('not depressed breakdwon 0-7'!D8+'not depressed breakdwon 0-7'!E8+'not depressed breakdwon 0-7'!F8+'not depressed breakdwon 0-7'!G8+'not depressed breakdwon 0-7'!I8+'not depressed breakdwon 0-7'!J8+'not depressed breakdwon 0-7'!K8+'not depressed breakdwon 0-7'!N8+'not depressed breakdwon 0-7'!O8+'not depressed breakdwon 0-7'!P8+'not depressed breakdwon 0-7'!Q8+'not depressed breakdwon 0-7'!R8+'not depressed breakdwon 0-7'!S8+'not depressed breakdwon 0-7'!T8+'not depressed breakdwon 0-7'!U8+'not depressed breakdwon 0-7'!W8+'not depressed breakdwon 0-7'!X8+'not depressed breakdwon 0-7'!Z8+'not depressed breakdwon 0-7'!AA8+'not depressed breakdwon 0-7'!AB8+'not depressed breakdwon 0-7'!AC8+'not depressed breakdwon 0-7'!AD8+'not depressed breakdwon 0-7'!AE8+'not depressed breakdwon 0-7'!AF8+'not depressed breakdwon 0-7'!AG8+'not depressed breakdwon 0-7'!AI8+'not depressed breakdwon 0-7'!AJ8+'not depressed breakdwon 0-7'!AK8+'not depressed breakdwon 0-7'!AL8+'not depressed breakdwon 0-7'!AO8+'not depressed breakdwon 0-7'!AP8+'not depressed breakdwon 0-7'!AR8+'not depressed breakdwon 0-7'!AS8+'not depressed breakdwon 0-7'!AT8+'not depressed breakdwon 0-7'!AU8+'not depressed breakdwon 0-7'!AV8+'not depressed breakdwon 0-7'!AW8)/37 -> 1.6216216 | E8: 1.7166667
A9: fear | B9: anger | C9: =('depressed breakdown 0-7'!A9+'depressed breakdown 0-7'!B9+'depressed breakdown 0-7'!C9+'depressed breakdown 0-7'!D9+'depressed breakdown 0-7'!E9+'depressed breakdown 0-7'!F9+'depressed breakdown 0-7'!G9+'depressed breakdown 0-7'!H9+'depressed breakdown 0-7'!I9+'depressed breakdown 0-7'!J9+'depressed breakdown 0-7'!K9+'depressed breakdown 0-7'!L9+'depressed breakdown 0-7'!M9+'depressed breakdown 0-7'!N9+'depressed breakdown 0-7'!O9+'depressed breakdown 0-7'!P9+'depressed breakdown 0-7'!Q9+'depressed breakdown 0-7'!R9)/18 -> 4.9444444 | D9: =('not depressed breakdwon 0-7'!D9+'not depressed breakdwon 0-7'!E9+'not depressed breakdwon 0-7'!F9+'not depressed breakdwon 0-7'!G9+'not depressed breakdwon 0-7'!I9+'not depressed breakdwon 0-7'!J9+'not depressed breakdwon 0-7'!K9+'not depressed breakdwon 0-7'!N9+'not depressed breakdwon 0-7'!O9+'not depressed breakdwon 0-7'!P9+'not depressed breakdwon 0-7'!Q9+'not depressed breakdwon 0-7'!R9+'not depressed breakdwon 0-7'!S9+'not depressed breakdwon 0-7'!T9+'not depressed breakdwon 0-7'!U9+'not depressed breakdwon 0-7'!W9+'not depressed breakdwon 0-7'!X9+'not depressed breakdwon 0-7'!Z9+'not depressed breakdwon 0-7'!AA9+'not depressed breakdwon 0-7'!AB9+'not depressed breakdwon 0-7'!AC9+'not depressed breakdwon 0-7'!AD9+'not depressed breakdwon 0-7'!AE9+'not depressed breakdwon 0-7'!AF9+'not depressed breakdwon 0-7'!AG9+'not depressed breakdwon 0-7'!AI9+'not depressed breakdwon 0-7'!AJ9+'not depressed breakdwon 0-7'!AK9+'not depressed breakdwon 0-7'!AL9+'not depressed breakdwon 0-7'!AO9+'not depressed breakdwon 0-7'!AP9+'not depressed breakdwon 0-7'!AR9+'not depressed breakdwon 0-7'!AS9+'not depressed breakdwon 0-7'!AT9+'not depressed breakdwon 0-7'!AU9+'not depressed breakdwon 0-7'!AV9+'not depressed breakdwon 0-7'!AW9)/37 -> 4.4324324 | E9: 4.7083333
A10: pink | B10: green | C10: =('depressed breakdown 0-7'!A10+'depressed breakdown 0-7'!B10+'depressed breakdown 0-7'!C10+'depressed breakdown 0-7'!D10+'depressed breakdown 0-7'!E10+'depressed breakdown 0-7'!F10+'depressed breakdown 0-7'!G10+'depressed breakdown 0-7'!H10+'depressed breakdown 0-7'!I10+'depressed breakdown 0-7'!J10+'depressed breakdown 0-7'!K10+'depressed breakdown 0-7'!L10+'depressed breakdown 0-7'!M10+'depressed breakdown 0-7'!N10+'depressed breakdown 0-7'!O10+'depressed breakdown 0-7'!P10+'depressed breakdown 0-7'!Q10+'depressed breakdown 0-7'!R10)/18 -> 3.0555556 | D10: =('not depressed breakdwon 0-7'!D10+'not depressed breakdwon 0-7'!E10+'not depressed breakdwon 0-7'!F10+'not depressed breakdwon 0-7'!G10+'not depressed breakdwon 0-7'!I10+'not depressed breakdwon 0-7'!J10+'not depressed breakdwon 0-7'!K10+'not depressed breakdwon 0-7'!N10+'not depressed breakdwon 0-7'!O10+'not depressed breakdwon 0-7'!P10+'not depressed breakdwon 0-7'!Q10+'not depressed breakdwon 0-7'!R10+'not depressed breakdwon 0-7'!S10+'not depressed breakdwon 0-7'!T10+'not depressed breakdwon 0-7'!U10+'not depressed breakdwon 0-7'!W10+'not depressed breakdwon 0-7'!X10+'not depressed breakdwon 0-7'!Z10+'not depressed breakdwon 0-7'!AA10+'not depressed breakdwon 0-7'!AB10+'not depressed breakdwon 0-7'!AC10+'not depressed breakdwon 0-7'!AD10+'not depressed breakdwon 0-7'!AE10+'not depressed breakdwon 0-7'!AF10+'not depressed breakdwon 0-7'!AG10+'not depressed breakdwon 0-7'!AI10+'not depressed breakdwon 0-7'!AJ10+'not depressed breakdwon 0-7'!AK10+'not depressed breakdwon 0-7'!AL10+'not depressed breakdwon 0-7'!AO10+'not depressed breakdwon 0-7'!AP10+'not depressed breakdwon 0-7'!AR10+'not depressed breakdwon 0-7'!AS10+'not depressed breakdwon 0-7'!AT10+'not depressed breakdwon 0-7'!AU10+'not depressed breakdwon 0-7'!AV10+'not depressed breakdwon 0-7'!AW10)/37 -> 3.1351351 | E10: 3.3916667
A11: blue | B11: anger | C11: =('depressed breakdown 0-7'!A11+'depressed breakdown 0-7'!B11+'depressed breakdown 0-7'!C11+'depressed breakdown 0-7'!D11+'depressed breakdown 0-7'!E11+'depressed breakdown 0-7'!F11+'depressed breakdown 0-7'!G11+'depressed breakdown 0-7'!H11+'depressed breakdown 0-7'!I11+'depressed breakdown 0-7'!J11+'depressed breakdown 0-7'!K11+'depressed breakdown 0-7'!L11+'depressed breakdown 0-7'!M11+'depressed breakdown 0-7'!N11+'depressed breakdown 0-7'!O11+'depressed breakdown 0-7'!P11+'depressed breakdown 0-7'!Q11+'depressed breakdown 0-7'!R11)/18 -> 1.6111111 | D11: =('not depressed breakdwon 0-7'!D11+'not depressed breakdwon 0-7'!E11+'not depressed breakdwon 0-7'!F11+'not depressed breakdwon 0-7'!G11+'not depressed breakdwon 0-7'!I11+'not depressed breakdwon 0-7'!J11+'not depressed breakdwon 0-7'!K11+'not depressed breakdwon 0-7'!N11+'not depressed breakdwon 0-7'!O11+'not depressed breakdwon 0-7'!P11+'not depressed breakdwon 0-7'!Q11+'not depressed breakdwon 0-7'!R11+'not depressed breakdwon 0-7'!S11+'not depressed breakdwon 0-7'!T11+'not depressed breakdwon 0-7'!U11+'not depressed breakdwon 0-7'!W11+'not depressed breakdwon 0-7'!X11+'not depressed breakdwon 0-7'!Z11+'not depressed breakdwon 0-7'!AA11+'not depressed breakdwon 0-7'!AB11+'not depressed breakdwon 0-7'!AC11+'not depressed breakdwon 0-7'!AD11+'not depressed breakdwon 0-7'!AE11+'not depressed breakdwon 0-7'!AF11+'not depressed breakdwon 0-7'!AG11+'not depressed breakdwon 0-7'!AI11+'not depressed breakdwon 0-7'!AJ11+'not depressed breakdwon 0-7'!AK11+'not depressed breakdwon 0-7'!AL11+'not depressed breakdwon 0-7'!AO11+'not depressed breakdwon 0-7'!AP11+'not depressed breakdwon 0-7'!AR11+'not depressed breakdwon 0-7'!AS11+'not depressed breakdwon 0-7'!AT11+'not depressed breakdwon 0-7'!AU11+'not depressed breakdwon 0-7'!AV11+'not depressed breakdwon 0-7'!AW11)/37 -> 1.3243243 | E11: 1.3583333
A12: green | B12: joy | C12: =('depressed breakdown 0-7'!A12+'depressed breakdown 0-7'!B12+'depressed breakdown 0-7'!C12+'depressed breakdown 0-7'!D12+'depressed breakdown 0-7'!E12+'depressed breakdown 0-7'!F12+'depressed breakdown 0-7'!G12+'depressed breakdown 0-7'!H12+'depressed breakdown 0-7'!I12+'depressed breakdown 0-7'!J12+'depressed breakdown 0-7'!K12+'depressed breakdown 0-7'!L12+'depressed breakdown 0-7'!M12+'depressed breakdown 0-7'!N12+'depressed breakdown 0-7'!O12+'depressed breakdown 0-7'!P12+'depressed breakdown 0-7'!Q12+'depressed breakdown 0-7'!R12)/18 -> 2.8333333 | D12: =('not depressed breakdwon 0-7'!D12+'not depressed breakdwon 0-7'!E12+'not depressed breakdwon 0-7'!F12+'not depressed breakdwon 0-7'!G12+'not depressed breakdwon 0-7'!I12+'not depressed breakdwon 0-7'!J12+'not depressed breakdwon 0-7'!K12+'not depressed breakdwon 0-7'!N12+'not depressed breakdwon 0-7'!O12+'not depressed breakdwon 0-7'!P12+'not depressed breakdwon 0-7'!Q12+'not depressed breakdwon 0-7'!R12+'not depressed breakdwon 0-7'!S12+'not depressed breakdwon 0-7'!T12+'not depressed breakdwon 0-7'!U12+'not depressed breakdwon 0-7'!W12+'not depressed breakdwon 0-7'!X12+'not depressed breakdwon 0-7'!Z12+'not depressed breakdwon 0-7'!AA12+'not depressed breakdwon 0-7'!AB12+'not depressed breakdwon 0-7'!AC12+'not depressed breakdwon 0-7'!AD12+'not depressed breakdwon 0-7'!AE12+'not depressed breakdwon 0-7'!AF12+'not depressed breakdwon 0-7'!AG12+'not depressed breakdwon 0-7'!AI12+'not depressed breakdwon 0-7'!AJ12+'not depressed breakdwon 0-7'!AK12+'not depressed breakdwon 0-7'!AL12+'not depressed breakdwon 0-7'!AO12+'not depressed breakdwon 0-7'!AP12+'not depressed breakdwon 0-7'!AR12+'not depressed breakdwon 0-7'!AS12+'not depressed breakdwon 0-7'!AT12+'not depressed breakdwon 0-7'!AU12+'not depressed breakdwon 0-7'!AV12+'not depressed breakdwon 0-7'!AW12)/37 -> 2.8918919 | E12: 2.8
A13: anger | B13: defeated | C13: =('depressed breakdown 0-7'!A13+'depressed breakdown 0-7'!B13+'depressed breakdown 0-7'!C13+'depressed breakdown 0-7'!D13+'depressed breakdown 0-7'!E13+'depressed breakdown 0-7'!F13+'depressed breakdown 0-7'!G13+'depressed breakdown 0-7'!H13+'depressed breakdown 0-7'!I13+'depressed breakdown 0-7'!J13+'depressed breakdown 0-7'!K13+'depressed breakdown 0-7'!L13+'depressed breakdown 0-7'!M13+'depressed breakdown 0-7'!N13+'depressed breakdown 0-7'!O13+'depressed breakdown 0-7'!P13+'depressed breakdown 0-7'!Q13+'depressed breakdown 0-7'!R13)/18 -> 4.4444444 | D13: =('not depressed breakdwon 0-7'!D13+'not depressed breakdwon 0-7'!E13+'not depressed breakdwon 0-7'!F13+'not depressed breakdwon 0-7'!G13+'not depressed breakdwon 0-7'!I13+'not depressed breakdwon 0-7'!J13+'not depressed breakdwon 0-7'!K13+'not depressed breakdwon 0-7'!N13+'not depressed breakdwon 0-7'!O13+'not depressed breakdwon 0-7'!P13+'not depressed breakdwon 0-7'!Q13+'not depressed breakdwon 0-7'!R13+'not depressed breakdwon 0-7'!S13+'not depressed breakdwon 0-7'!T13+'not depressed breakdwon 0-7'!U13+'not depressed breakdwon 0-7'!W13+'not depressed breakdwon 0-7'!X13+'not depressed breakdwon 0-7'!Z13+'not depressed breakdwon 0-7'!AA13+'not depressed breakdwon 0-7'!AB13+'not depressed breakdwon 0-7'!AC13+'not depressed breakdwon 0-7'!AD13+'not depressed breakdwon 0-7'!AE13+'not depressed breakdwon 0-7'!AF13+'not depressed breakdwon 0-7'!AG13+'not depressed breakdwon 0-7'!AI13+'not depressed breakdwon 0-7'!AJ13+'not depressed breakdwon 0-7'!AK13+'not depressed breakdwon 0-7'!AL13+'not depressed breakdwon 0-7'!AO13+'not depressed breakdwon 0-7'!AP13+'not depressed breakdwon 0-7'!AR13+'not depressed breakdwon 0-7'!AS13+'not depressed breakdwon 0-7'!AT13+'not depressed breakdwon 0-7'!AU13+'not depressed breakdwon 0-7'!AV13+'not depressed breakdwon 0-7'!AW13)/37 -> 4.1621622 | E13: 4.1083333
... A254: anxiety | B254: boredom | C254: =('depressed breakdown 0-7'!A254+'depressed breakdown 0-7'!B254+'depressed breakdown 0-7'!C254+'depressed breakdown 0-7'!D254+'depressed breakdown 0-7'!E254+'depressed breakdown 0-7'!F254+'depressed breakdown 0-7'!G254+'depressed breakdown 0-7'!H254+'depressed breakdown 0-7'!I254+'depressed breakdown 0-7'!J254+'depressed breakdown 0-7'!K254+'depressed breakdown 0-7'!L254+'depressed breakdown 0-7'!M254+'depressed breakdown 0-7'!N254+'depressed breakdown 0-7'!O254+'depressed breakdown 0-7'!P254+'depressed breakdown 0-7'!Q254+'depressed breakdown 0-7'!R254)/18 -> 3.5 | D254: =('not depressed breakdwon 0-7'!D254+'not depressed breakdwon 0-7'!E254+'not depressed breakdwon 0-7'!F254+'not depressed breakdwon 0-7'!G254+'not depressed breakdwon 0-7'!I254+'not depressed breakdwon 0-7'!J254+'not depressed breakdwon 0-7'!K254+'not depressed breakdwon 0-7'!N254+'not depressed breakdwon 0-7'!O254+'not depressed breakdwon 0-7'!P254+'not depressed breakdwon 0-7'!Q254+'not depressed breakdwon 0-7'!R254+'not depressed breakdwon 0-7'!S254+'not depressed breakdwon 0-7'!T254+'not depressed breakdwon 0-7'!U254+'not depressed breakdwon 0-7'!W254+'not depressed breakdwon 0-7'!X254+'not depressed breakdwon 0-7'!Z254+'not depressed breakdwon 0-7'!AA254+'not depressed breakdwon 0-7'!AB254+'not depressed breakdwon 0-7'!AC254+'not depressed breakdwon 0-7'!AD254+'not depressed breakdwon 0-7'!AE254+'not depressed breakdwon 0-7'!AF254+'not depressed breakdwon 0-7'!AG254+'not depressed breakdwon 0-7'!AI254+'not depressed breakdwon 0-7'!AJ254+'not depressed breakdwon 0-7'!AK254+'not depressed breakdwon 0-7'!AL254+'not depressed breakdwon 0-7'!AO254+'not depressed breakdwon 0-7'!AP254+'not depressed breakdwon 0-7'!AR254+'not depressed breakdwon 0-7'!AS254+'not depressed breakdwon 0-7'!AT254+'not depressed breakdwon 0-7'!AU254+'not depressed breakdwon 0-7'!AV254+'not depressed breakdwon 0-7'!AW254)/37 -> 2.8108108 | E254: 3.125

Sheet converted to 0-7 ALL
A1: BDI | C1: 24 | D1: 11 | E1: 13 | F1: 22 | G1: 11 | H1: 21 | I1: 9 | J1: 5 | K1: 5 | L1: 9 | M1: 20 | N1: 34 | O1: 24 | P1: 0 | Q1: 1 | R1: 10 | S1: 0 | T1: 29 | U1: 0 | V1: 31 | W1: 2 | X1: 1 | Y1: 10 | Z1: 1 | AA1: 0 | AB1: 18 | AC1: 9 | AD1: 29 | AE1: 0 | AF1: 6 | AG1: 29 | AH1: 0 | AI1: 7 | AJ1: 0 | AK1: 0 | AL1: 0 | AM1: 21 | AN1: 21 | AO1: 25 | AP1: 10 | AQ1: 6 | AR1: 34 | AS1: 16 | AT1: 0 | AU1: 19 | AV1: 25 | AW1: 3 | AX1: 28 | AY1: 18 | AZ1: 39 | BA1: 0 | BB1: 25 | BC1: 7 | BD1: 7 | BE1: 12 | BF1: 7 | BG1: 38 | BH1: 3 | BI1: 15 | BJ1: 6 | BK1: 4 | BL1: 7 | BM1: 0 | BN1: 14 | BO1: 3 | BP1: 11 | BQ1: 20 | BR1: 1 | BS1: 8 | BT1: 0 | BU1: 36 | BV1: 18 | BW1: 0 | BX1: 8 | BY1: 10 | BZ1: 11 | CA1: 4 | CB1: 10 | CC1: 5 | CD1: 1 | CE1: 0 | CF1: 12 | CG1: 26 | CH1: 19 | CI1: 0 | CJ1: 1 | CK1: 29 | CL1: 17 | CM1: 1 | CN1: 26 | CO1: 16 | CP1: 12 | CQ1: 13 | CR1: 6 | CS1: 0 | CT1: 10 | CU1: 2 | CV1: 1 | CW1: 0 | CX1: 26 | CY1: 1 | CZ1: 7 | DA1: 4 | DB1: 8 | DC1: 0 | DD1: 4 | DE1: 39 | DF1: 1 | DG1: 17 | DH1: 17 | DI1: 0 | DJ1: 15 | DK1: 9 | DL1: 19 | DM1: 14 | DN1: 5 | DO1: 18 | DP1: 5 | DQ1: 14 | DR1: 32
A2: brown | B2: anger | C2: =IF('w.o double'!C2<0, 'w.o double'!C2+4, 'w.o double'!C2+3) -> 0 | D2: =IF('w.o double'!D2<0, 'w.o double'!D2+4, 'w.o double'!D2+3) -> 0 | E2: =IF('w.o double'!E2<0, 'w.o double'!E2+4, 'w.o double'!E2+3) -> 0 | F2: =IF('w.o double'!F2<0, 'w.o double'!F2+4, 'w.o double'!F2+3) -> 6 | G2: =IF('w.o double'!G2<0, 'w.o double'!G2+4, 'w.o double'!G2+3) -> 1 | H2: =IF('w.o double'!H2<0, 'w.o double'!H2+4, 'w.o double'!H2+3) -> 2 | I2: =IF('w.o double'!I2<0, 'w.o double'!I2+4, 'w.o double'!I2+3) -> 1 | J2: =IF('w.o double'!J2<0, 'w.o double'!J2+4, 'w.o double'!J2+3) -> 7 | ... DR2: =IF('w.o double'!DR2<0, 'w.o double'!DR2+4, 'w.o double'!DR2+3) -> 2 | DS2: =SUM(C2:DR2) -> 139 | DT2: =DS2/120 -> 1.1583333
A3: orange | B3: anxiety | C3: =IF('w.o double'!C3<0, 'w.o double'!C3+4, 'w.o double'!C3+3) -> 0 | D3: =IF('w.o double'!D3<0, 'w.o double'!D3+4, 'w.o double'!D3+3) -> 0 | E3: =IF('w.o double'!E3<0, 'w.o double'!E3+4, 'w.o double'!E3+3) -> 1 | F3: =IF('w.o double'!F3<0, 'w.o double'!F3+4, 'w.o double'!F3+3) -> 2 | G3: =IF('w.o double'!G3<0, 'w.o double'!G3+4, 'w.o double'!G3+3) -> 0 | H3: =IF('w.o double'!H3<0, 'w.o double'!H3+4, 'w.o double'!H3+3) -> 0 | I3: =IF('w.o double'!I3<0, 'w.o double'!I3+4, 'w.o double'!I3+3) -> 1 | J3: =IF('w.o double'!J3<0, 'w.o double'!J3+4, 'w.o double'!J3+3) -> 0 | ... DR3: =IF('w.o double'!DR3<0, 'w.o double'!DR3+4, 'w.o double'!DR3+3) -> 4 | DS3: =SUM(C3:DR3) -> 186 | DT3: =DS3/120 -> 1.55
A4: red | B4: yellow | C4: =IF('w.o double'!C4<0, 'w.o double'!C4+4, 'w.o double'!C4+3) -> 4 | D4: =IF('w.o double'!D4<0, 'w.o double'!D4+4, 'w.o double'!D4+3) -> 1 | E4: =IF('w.o double'!E4<0, 'w.o double'!E4+4, 'w.o double'!E4+3) -> 2 | F4: =IF('w.o double'!F4<0, 'w.o double'!F4+4, 'w.o double'!F4+3) -> 5 | G4: =IF('w.o double'!G4<0, 'w.o double'!G4+4, 'w.o double'!G4+3) -> 4 | H4: =IF('w.o double'!H4<0, 'w.o double'!H4+4, 'w.o double'!H4+3) -> 4 | I4: =IF('w.o double'!I4<0, 'w.o double'!I4+4, 'w.o double'!I4+3) -> 3 | J4: =IF('w.o double'!J4<0, 'w.o double'!J4+4, 'w.o double'!J4+3) -> 7 | ... DR4: =IF('w.o double'!DR4<0, 'w.o double'!DR4+4, 'w.o double'!DR4+3) -> 6 | DS4: =SUM(C4:DR4) -> 465 | DT4: =DS4/120 -> 3.875
A5: black | B5: blue | C5: =IF('w.o double'!C5<0, 'w.o double'!C5+4, 'w.o double'!C5+3) -> 4 | D5: =IF('w.o double'!D5<0, 'w.o double'!D5+4, 'w.o double'!D5+3) -> 0 | E5: =IF('w.o double'!E5<0, 'w.o double'!E5+4, 'w.o double'!E5+3) -> 1 | F5: =IF('w.o double'!F5<0, 'w.o double'!F5+4, 'w.o double'!F5+3) -> 6 | G5: =IF('w.o double'!G5<0, 'w.o double'!G5+4, 'w.o double'!G5+3) -> 3 | H5: =IF('w.o double'!H5<0, 'w.o double'!H5+4, 'w.o double'!H5+3) -> 6 | I5: =IF('w.o double'!I5<0, 'w.o double'!I5+4, 'w.o double'!I5+3) -> 3 | J5: =IF('w.o double'!J5<0, 'w.o double'!J5+4, 'w.o double'!J5+3) -> 7 | ... DR5: =IF('w.o double'!DR5<0, 'w.o double'!DR5+4, 'w.o double'!DR5+3) -> 6 | DS5: =SUM(C5:DR5) -> 535 | DT5: =DS5/120 -> 4.4583333
A6: green | B6: calm | C6: =IF('w.o double'!C6<0, 'w.o double'!C6+4, 'w.o double'!C6+3) -> 5 | D6: =IF('w.o double'!D6<0, 'w.o double'!D6+4, 'w.o double'!D6+3) -> 2 | E6: =IF('w.o double'!E6<0, 'w.o double'!E6+4, 'w.o double'!E6+3) -> 5 | F6: =IF('w.o double'!F6<0, 'w.o double'!F6+4, 'w.o double'!F6+3) -> 5 | G6: =IF('w.o double'!G6<0, 'w.o double'!G6+4, 'w.o double'!G6+3) -> 0 | H6: =IF('w.o double'!H6<0, 'w.o double'!H6+4, 'w.o double'!H6+3) -> 6 | I6: =IF('w.o double'!I6<0, 'w.o double'!I6+4, 'w.o double'!I6+3) -> 3 | J6: =IF('w.o double'!J6<0, 'w.o double'!J6+4, 'w.o double'!J6+3) -> 7 | ... DR6: =IF('w.o double'!DR6<0, 'w.o double'!DR6+4, 'w.o double'!DR6+3) -> 5 | DS6: =SUM(C6:DR6) -> 416 | DT6: =DS6/120 -> 3.4666667
A7: red | B7: pink | C7: =IF('w.o double'!C7<0, 'w.o double'!C7+4, 'w.o double'!C7+3) -> 6 | D7: =IF('w.o double'!D7<0, 'w.o double'!D7+4, 'w.o double'!D7+3) -> 1 | E7: =IF('w.o double'!E7<0, 'w.o double'!E7+4, 'w.o double'!E7+3) -> 4 | F7: =IF('w.o double'!F7<0, 'w.o double'!F7+4, 'w.o double'!F7+3) -> 6 | G7: =IF('w.o double'!G7<0, 'w.o double'!G7+4, 'w.o double'!G7+3) -> 6 | H7: =IF('w.o double'!H7<0, 'w.o double'!H7+4, 'w.o double'!H7+3) -> 6 | I7: =IF('w.o double'!I7<0, 'w.o double'!I7+4, 'w.o double'!I7+3) -> 3 | J7: =IF('w.o double'!J7<0, 'w.o double'!J7+4, 'w.o double'!J7+3) -> 7 | ... DR7: =IF('w.o double'!DR7<0, 'w.o double'!DR7+4, 'w.o double'!DR7+3) -> 6 | DS7: =SUM(C7:DR7) -> 629 | DT7: =DS7/120 -> 5.2416667
A8: envy | B8: joy | C8: =IF('w.o double'!C8<0, 'w.o double'!C8+4, 'w.o double'!C8+3) -> 3 | D8: =IF('w.o double'!D8<0, 'w.o double'!D8+4, 'w.o double'!D8+3) -> 0 | E8: =IF('w.o double'!E8<0, 'w.o double'!E8+4, 'w.o double'!E8+3) -> 0 | F8: =IF('w.o double'!F8<0, 'w.o double'!F8+4, 'w.o double'!F8+3) -> 2 | G8: =IF('w.o double'!G8<0, 'w.o double'!G8+4, 'w.o double'!G8+3) -> 1 | H8: =IF('w.o double'!H8<0, 'w.o double'!H8+4, 'w.o double'!H8+3) -> 0 | I8: =IF('w.o double'!I8<0, 'w.o double'!I8+4, 'w.o double'!I8+3) -> 2 | J8: =IF('w.o double'!J8<0, 'w.o double'!J8+4, 'w.o double'!J8+3) -> 0 | ... DR8: =IF('w.o double'!DR8<0, 'w.o double'!DR8+4, 'w.o double'!DR8+3) -> 3 | DS8: =SUM(C8:DR8) -> 206 | DT8: =DS8/120 -> 1.7166667
A9: fear | B9: anger | C9: =IF('w.o double'!C9<0, 'w.o double'!C9+4, 'w.o double'!C9+3) -> 6 | D9: =IF('w.o double'!D9<0, 'w.o double'!D9+4, 'w.o double'!D9+3) -> 5 | E9: =IF('w.o double'!E9<0, 'w.o double'!E9+4, 'w.o double'!E9+3) -> 2 | F9: =IF('w.o double'!F9<0, 'w.o double'!F9+4, 'w.o double'!F9+3) -> 5 | G9: =IF('w.o double'!G9<0, 'w.o double'!G9+4, 'w.o double'!G9+3) -> 5 | H9: =IF('w.o double'!H9<0, 'w.o double'!H9+4, 'w.o double'!H9+3) -> 7 | I9: =IF('w.o double'!I9<0, 'w.o double'!I9+4, 'w.o double'!I9+3) -> 4 | J9: =IF('w.o double'!J9<0, 'w.o double'!J9+4, 'w.o double'!J9+3) -> 7 | ... DR9: =IF('w.o double'!DR9<0, 'w.o double'!DR9+4, 'w.o double'!DR9+3) -> 4 | DS9: =SUM(C9:DR9) -> 565 | DT9: =DS9/120 -> 4.7083333
A10: pink | B10: green | C10: =IF('w.o double'!C10<0, 'w.o double'!C10+4, 'w.o double'!C10+3) -> 4 | D10: =IF('w.o double'!D10<0, 'w.o double'!D10+4, 'w.o double'!D10+3) -> 1 | E10: =IF('w.o double'!E10<0, 'w.o double'!E10+4, 'w.o double'!E10+3) -> 1 | F10: =IF('w.o double'!F10<0, 'w.o double'!F10+4, 'w.o double'!F10+3) -> 3 | G10: =IF('w.o double'!G10<0, 'w.o double'!G10+4, 'w.o double'!G10+3) -> 2 | H10: =IF('w.o double'!H10<0, 'w.o double'!H10+4, 'w.o double'!H10+3) -> 1 | I10: =IF('w.o double'!I10<0, 'w.o double'!I10+4, 'w.o double'!I10+3) -> 3 | J10: =IF('w.o double'!J10<0, 'w.o double'!J10+4, 'w.o double'!J10+3) -> 0 | ... DR10: =IF('w.o double'!DR10<0, 'w.o double'!DR10+4, 'w.o double'!DR10+3) -> 3 | DS10: =SUM(C10:DR10) -> 407 | DT10: =DS10/120 -> 3.3916667
A11: blue | B11: anger | C11: =IF('w.o double'!C11<0, 'w.o double'!C11+4, 'w.o double'!C11+3) -> 2 | D11: =IF('w.o double'!D11<0, 'w.o double'!D11+4, 'w.o double'!D11+3) -> 0 | E11: =IF('w.o double'!E11<0, 'w.o double'!E11+4, 'w.o double'!E11+3) -> 0 | F11: =IF('w.o double'!F11<0, 'w.o double'!F11+4, 'w.o double'!F11+3) -> 4 | G11: =IF('w.o double'!G11<0, 'w.o double'!G11+4, 'w.o double'!G11+3) -> 0 | H11: =IF('w.o double'!H11<0, 'w.o double'!H11+4, 'w.o double'!H11+3) -> 0 | I11: =IF('w.o double'!I11<0, 'w.o double'!I11+4, 'w.o double'!I11+3) -> 2 | J11: =IF('w.o double'!J11<0, 'w.o double'!J11+4, 'w.o double'!J11+3) -> 0 | ... DR11: =IF('w.o double'!DR11<0, 'w.o double'!DR11+4, 'w.o double'!DR11+3) -> 2 | DS11: =SUM(C11:DR11) -> 163 | DT11: =DS11/120 -> 1.3583333
A12: green | B12: joy | C12: =IF('w.o double'!C12<0, 'w.o double'!C12+4, 'w.o double'!C12+3) -> 5 | D12: =IF('w.o double'!D12<0, 'w.o double'!D12+4, 'w.o double'!D12+3) -> 2 | E12: =IF('w.o double'!E12<0, 'w.o double'!E12+4, 'w.o double'!E12+3) -> 4 | F12: =IF('w.o double'!F12<0, 'w.o double'!F12+4, 'w.o double'!F12+3) -> 3 | G12: =IF('w.o double'!G12<0, 'w.o double'!G12+4, 'w.o double'!G12+3) -> 2 | H12: =IF('w.o double'!H12<0, 'w.o double'!H12+4, 'w.o double'!H12+3) -> 6 | I12: =IF('w.o double'!I12<0, 'w.o double'!I12+4, 'w.o double'!I12+3) -> 3 | J12: =IF('w.o double'!J12<0, 'w.o double'!J12+4, 'w.o double'!J12+3) -> 0 | ... DR12: =IF('w.o double'!DR12<0, 'w.o double'!DR12+4, 'w.o double'!DR12+3) -> 3 | DS12: =SUM(C12:DR12) -> 336 | DT12: =DS12/120 -> 2.8
A13: anger | B13: defeated | C13: =IF('w.o double'!C13<0, 'w.o double'!C13+4, 'w.o double'!C13+3) -> 5 | D13: =IF('w.o double'!D13<0, 'w.o double'!D13+4, 'w.o double'!D13+3) -> 5 | E13: =IF('w.o double'!E13<0, 'w.o double'!E13+4, 'w.o double'!E13+3) -> 2 | F13: =IF('w.o double'!F13<0, 'w.o double'!F13+4, 'w.o double'!F13+3) -> 4 | G13: =IF('w.o double'!G13<0, 'w.o double'!G13+4, 'w.o double'!G13+3) -> 4 | H13: =IF('w.o double'!H13<0, 'w.o double'!H13+4, 'w.o double'!H13+3) -> 7 | I13: =IF('w.o double'!I13<0, 'w.o double'!I13+4, 'w.o double'!I13+3) -> 4 | J13: =IF('w.o double'!J13<0, 'w.o double'!J13+4, 'w.o double'!J13+3) -> 1 | ... DR13: =IF('w.o double'!DR13<0, 'w.o double'!DR13+4, 'w.o double'!DR13+3) -> 4 | DS13: =SUM(C13:DR13) -> 493 | DT13: =DS13/120 -> 4.1083333
... A254: anxiety | B254: boredom | C254: =IF('w.o double'!C254<0, 'w.o double'!C254+4, 'w.o double'!C254+3) -> 2 | D254: =IF('w.o double'!D254<0, 'w.o double'!D254+4, 'w.o double'!D254+3) -> 4 | E254: =IF('w.o double'!E254<0, 'w.o double'!E254+4, 'w.o double'!E254+3) -> 1 | F254: =IF('w.o double'!F254<0, 'w.o double'!F254+4, 'w.o double'!F254+3) -> 4 | G254: =IF('w.o double'!G254<0, 'w.o double'!G254+4, 'w.o double'!G254+3) -> 1 | H254: =IF('w.o double'!H254<0, 'w.o double'!H254+4, 'w.o double'!H254+3) -> 6 | I254: =IF('w.o double'!I254<0, 'w.o double'!I254+4, 'w.o double'!I254+3) -> 3 | J254: =IF('w.o double'!J254<0, 'w.o double'!J254+4, 'w.o double'!J254+3) -> 5 | ... DR254: =IF('w.o double'!DR254<0, 'w.o double'!DR254+4, 'w.o double'!DR254+3) -> 2 | DS254: =SUM(C254:DR254) -> 375 | DT254: =DS254/120 -> 3.125

Sheet converted to 0-7 ALL-value
A1: BDI | C1: 24 | D1: 11 | E1: 13 | F1: 22 | G1: 11 | H1: 21 | I1: 9 | J1: 5 | K1: 5 | L1: 9 | M1: 20 | N1: 34 | O1: 24 | P1: 0 | Q1: 1 | R1: 10 | S1: 0 | T1: 29 | U1: 0 | V1: 31 | W1: 2 | X1: 1 | Y1: 10 | Z1: 1 | AA1: 0 | AB1: 18 | AC1: 9 | AD1: 29 | AE1: 0 | AF1: 6 | AG1: 29 | AH1: 0 | AI1: 7 | AJ1: 0 | AK1: 0 | AL1: 0 | AM1: 21 | AN1: 21 | AO1: 25 | AP1: 10 | AQ1: 6 | AR1: 34 | AS1: 16 | AT1: 0 | AU1: 19 | AV1: 25 | AW1: 3 | AX1: 28 | AY1: 18 | AZ1: 39 | BA1: 0 | BB1: 25 | BC1: 7 | BD1: 7 | BE1: 12 | BF1: 7 | BG1: 38 | BH1: 3 | BI1: 15 | BJ1: 6 | BK1: 4 | BL1: 7 | BM1: 0 | BN1: 14 | BO1: 3 | BP1: 11 | BQ1: 20 | BR1: 1 | BS1: 8 | BT1: 0 | BU1: 36 | BV1: 18 | BW1: 0 | BX1: 8 | BY1: 10 | BZ1: 11 | CA1: 4 | CB1: 10 | CC1: 5 | CD1: 1 | CE1: 0 | CF1: 12 | CG1: 26 | CH1: 19 | CI1: 0 | CJ1: 1 | CK1: 29 | CL1: 17 | CM1: 1 | CN1: 26 | CO1: 16 | CP1: 12 | CQ1: 13 | CR1: 6 | CS1: 0 | CT1: 10 | CU1: 2 | CV1: 1 | CW1: 0 | CX1: 26 | CY1: 1 | CZ1: 7 | DA1: 4 | DB1: 8 | DC1: 0 | DD1: 4 | DE1: 39 | DF1: 1 | DG1: 17 | DH1: 17 | DI1: 0 | DJ1: 15 | DK1: 9 | DL1: 19 | DM1: 14 | DN1: 5 | DO1: 18 | DP1: 5 | DQ1: 14 | DR1: 32
A2: brown | B2: anger | C2: 0 | D2: 0 | E2: 0 | F2: 6 | G2: 1 | H2: 2 | I2: 1 | J2: 7 | K2: 2 | L2: 1 | M2: 6 | N2: 0 | O2: 0 | P2: 1 | Q2: 0 | R2: 1 | S2: 1 | T2: 1 | U2: 0 | V2: 0 | W2: 5 | X2: 4 | Y2: 0 | Z2: 3 | AA2: 0 | AB2: 1 | AC2: 2 | AD2: 1 | AE2: 3 | AF2: 0 | AG2: 3 | AH2: 0 | AI2: 1 | AJ2: 1 | AK2: 0 | AL2: 2 | AM2: 1 | AN2: 2 | AO2: 1 | AP2: 2 | AQ2: 3 | AR2: 1 | AS2: 0 | AT2: 0 | AU2: 1 | AV2: 0 | AW2: 0 | AX2: 0 | AY2: 0 | AZ2: 0 | BA2: 0 | BB2: 1 | BC2: 1 | BD2: 1 | BE2: 3 | BF2: 0 | BG2: 0 | BH2: 3 | BI2: 1 | BJ2: 0 | BK2: 2 | BL2: 1 | BM2: 2 | BN2: 1 | BO2: 0 | BP2: 0 | BQ2: 0 | BR2: 2 | BS2: 0 | BT2: 0 | BU2: 0 | BV2: 1 | BW2: 0 | BX2: 0 | BY2: 2 | BZ2: 0 | CA2: 0 | CB2: 1 | CC2: 0 | CD2: 1 | CE2: 0 | CF2: 3 | CG2: 3 | CH2: 1 | CI2: 2 | CJ2: 0 | CK2: 4 | CL2: 0 | CM2: 0 | CN2: 1 | CO2: 1 | CP2: 3 | CQ2: 0 | CR2: 0 | CS2: 0 | CT2: 2 | CU2: 2 | CV2: 1 | CW2: 4 | CX2: 4 | CY2: 2 | CZ2: 0 | DA2: 3 | DB2: 0 | DC2: 1 | DD2: 0 | DE2: 0 | DF2: 0 | DG2: 2 | DH2: 0 | DI2: 1 | DJ2: 0 | DK2: 0 | DL2: 0 | DM2: 2 | DN2: 3 | DO2: 1 | DP2: 1 | DQ2: 0 | DR2: 2 | DS2: =SUM(C2:DR2) -> 139 | DT2: =DS2/120 -> 1.1583333
A3: orange | B3: anxiety | C3: 0 | D3: 0 | E3: 1 | F3: 2 | G3: 0 | H3: 0 | I3: 1 | J3: 0 | K3: 5 | L3: 4 | M3: 3 | N3: 0 | O3: 0 | P3: 5 | Q3: 0 | R3: 0 | S3: 1 | T3: 0 | U3: 0 | V3: 0 | W3: 4 | X3: 1 | Y3: 0 | Z3: 4 | AA3: 0 | AB3: 2 | AC3: 1 | AD3: 1 | AE3: 1 | AF3: 2 | AG3: 1 | AH3: 2 | AI3: 1 | AJ3: 1 | AK3: 1 | AL3: 2 | AM3: 4 | AN3: 2 | AO3: 1 | AP3: 1 | AQ3: 2 | AR3: 1 | AS3: 0 | AT3: 0 | AU3: 5 | AV3: 0 | AW3: 1 | AX3: 0 | AY3: 1 | AZ3: 0 | BA3: 0 | BB3: 0 | BC3: 3 | BD3: 4 | BE3: 6 | BF3: 0 | BG3: 0 | BH3: 4 | BI3: 1 | BJ3: 1 | BK3: 3 | BL3: 2 | BM3: 1 | BN3: 3 | BO3: 2 | BP3: 5 | BQ3: 1 | BR3: 1 | BS3: 0 | BT3: 0 | BU3: 0 | BV3: 0 | BW3: 0 | BX3: 1 | BY3: 2 | BZ3: 0 | CA3: 1 | CB3: 1 | CC3: 0 | CD3: 1 | CE3: 0 | CF3: 6 | CG3: 5 | CH3: 1 | CI3: 1 | CJ3: 0 | CK3: 2 | CL3: 1 | CM3: 0 | CN3: 1 | CO3: 1 | CP3: 2 | CQ3: 0 | CR3: 0 | CS3: 0 | CT3: 3 | CU3: 4 | CV3: 1 | CW3: 3 | CX3: 1 | CY3: 5 | CZ3: 4 | DA3: 4 | DB3: 0 | DC3: 2 | DD3: 2 | DE3: 2 | DF3: 3 | DG3: 4 | DH3: 1 | DI3: 2 | DJ3: 0 | DK3: 0 | DL3: 1 | DM3: 1 | DN3: 2 | DO3: 5 | DP3: 1 | DQ3: 4 | DR3: 4 | DS3: =SUM(C3:DR3) -> 186 | DT3: =DS3/120 -> 1.55
A4: red | B4: yellow | C4: 4 | D4: 1 | E4: 2 | F4: 5 | G4: 4 | H4: 4 | I4: 3 | J4: 7 | K4: 0 | L4: 6 | M4: 4 | N4: 0 | O4: 1 | P4: 5 | Q4: 2 | R4: 5 | S4: 4 | T4: 4 | U4: 7 | V4: 3 | W4: 2 | X4: 4 | Y4: 4 | Z4: 4 | AA4: 7 | AB4: 6 | AC4: 3 | AD4: 2 | AE4: 5 | AF4: 6 | AG4: 0 | AH4: 2 | AI4: 7 | AJ4: 7 | AK4: 2 | AL4: 7 | AM4: 1 | AN4: 1 | AO4: 7 | AP4: 3 | AQ4: 2 | AR4: 7 | AS4: 4 | AT4: 6 | AU4: 4 | AV4: 5 | AW4: 6 | AX4: 6 | AY4: 5 | AZ4: 6 | BA4: 3 | BB4: 5 | BC4: 5 | BD4: 1 | BE4: 6 | BF4: 5 | BG4: 3 | BH4: 3 | BI4: 4 | BJ4: 4 | BK4: 3 | BL4: 1 | BM4: 4 | BN4: 0 | BO4: 4 | BP4: 4 | BQ4: 0 | BR4: 1 | BS4: 1 | BT4: 7 | BU4: 1 | BV4: 1 | BW4: 7 | BX4: 0 | BY4: 5 | BZ4: 1 | CA4: 7 | CB4: 4 | CC4: 5 | CD4: 1 | CE4: 7 | CF4: 5 | CG4: 4 | CH4: 2 | CI4: 0 | CJ4: 5 | CK4: 6 | CL4: 6 | CM4: 6 | CN4: 6 | CO4: 5 | CP4: 0 | CQ4: 7 | CR4: 4 | CS4: 5 | CT4: 2 | CU4: 6 | CV4: 5 | CW4: 5 | CX4: 4 | CY4: 2 | CZ4: 0 | DA4: 5 | DB4: 0 | DC4: 7 | DD4: 7 | DE4: 3 | DF4: 3 | DG4: 3 | DH4: 5 | DI4: 3 | DJ4: 4 | DK4: 7 | DL4: 2 | DM4: 4 | DN4: 4 | DO4: 7 | DP4: 5 | DQ4: 0 | DR4: 6 | DS4: =SUM(C4:DR4) -> 465 | DT4: =DS4/120 -> 3.875
A5: black | B5: blue | C5: 4 | D5: 0 | E5: 1 | F5: 6 | G5: 3 | H5: 6 | I5: 3 | J5: 7 | K5: 1 | L5: 6 | M5: 6 | N5: 4 | O5: 1 | P5: 6 | Q5: 6 | R5: 5 | S5: 1 | T5: 5 | U5: 5 | V5: 4 | W5: 5 | X5: 5 | Y5: 4 | Z5: 4 | AA5: 7 | AB5: 6 | AC5: 3 | AD5: 2 | AE5: 5 | AF5: 6 | AG5: 3 | AH5: 1 | AI5: 7 | AJ5: 7 | AK5: 4 | AL5: 7 | AM5: 4 | AN5: 3 | AO5: 6 | AP5: 5 | AQ5: 3 | AR5: 7 | AS5: 4 | AT5: 6 | AU5: 4 | AV5: 5 | AW5: 6 | AX5: 6 | AY5: 4 | AZ5: 5 | BA5: 2 | BB5: 5 | BC5: 2 | BD5: 5 | BE5: 6 | BF5: 6 | BG5: 4 | BH5: 5 | BI5: 5 | BJ5: 5 | BK5: 4 | BL5: 3 | BM5: 4 | BN5: 4 | BO5: 4 | BP5: 0 | BQ5: 0 | BR5: 5 | BS5: 1 | BT5: 6 | BU5: 2 | BV5: 2 | BW5: 7 | BX5: 1 | BY5: 6 | BZ5: 2 | CA5: 6 | CB5: 5 | CC5: 5 | CD5: 1 | CE5: 7 | CF5: 5 | CG5: 6 | CH5: 5 | CI5: 5 | CJ5: 5 | CK5: 6 | CL5: 5 | CM5: 6 | CN5: 7 | CO5: 3 | CP5: 5 | CQ5: 7 | CR5: 5 | CS5: 5 | CT5: 4 | CU5: 5 | CV5: 5 | CW5: 5 | CX5: 5 | CY5: 5 | CZ5: 3 | DA5: 5 | DB5: 5 | DC5: 7 | DD5: 4 | DE5: 3 | DF5: 5 | DG5: 4 | DH5: 6 | DI5: 3 | DJ5: 2 | DK5: 7 | DL5: 2 | DM5: 5 | DN5: 6 | DO5: 7 | DP5: 5 | DQ5: 2 | DR5: 6 | DS5: =SUM(C5:DR5) -> 535 | DT5: =DS5/120 -> 4.4583333
A6: green | B6: calm | C6: 5 | D6: 2 | E6: 5 | F6: 5 | G6: 0 | H6: 6 | I6: 3 | J6: 7 | K6: 6 | L6: 5 | M6: 2 | N6: 4 | O6: 1 | P6: 7 | Q6: 1 | R6: 1 | S6: 1 | T6: 5 | U6: 4 | V6: 1 | W6: 5 | X6: 7 | Y6: 4 | Z6: 5 | AA6: 5 | AB6: 1 | AC6: 4 | AD6: 4 | AE6: 0 | AF6: 2 | AG6: 5 | AH6: 5 | AI6: 4 | AJ6: 5 | AK6: 6 | AL6: 2 | AM6: 6 | AN6: 5 | AO6: 3 | AP6: 6 | AQ6: 4 | AR6: 2 | AS6: 2 | AT6: 0 | AU6: 4 | AV6: 5 | AW6: 5 | AX6: 5 | AY6: 1 | AZ6: 4 | BA6: 3 | BB6: 6 | BC6: 4 | BD6: 6 | BE6: 3 | BF6: 2 | BG6: 4 | BH6: 4 | BI6: 5 | BJ6: 4 | BK6: 4 | BL6: 6 | BM6: 5 | BN6: 2 | BO6: 1 | BP6: 7 | BQ6: 0 | BR6: 2 | BS6: 1 | BT6: 0 | BU6: 3 | BV6: 1 | BW6: 0 | BX6: 3 | BY6: 4 | BZ6: 0 | CA6: 1 | CB6: 1 | CC6: 0 | CD6: 4 | CE6: 0 | CF6: 7 | CG6: 2 | CH6: 3 | CI6: 7 | CJ6: 2 | CK6: 5 | CL6: 1 | CM6: 0 | CN6: 4 | CO6: 2 | CP6: 6 | CQ6: 1 | CR6: 1 | CS6: 0 | CT6: 6 | CU6: 5 | CV6: 1 | CW6: 3 | CX6: 6 | CY6: 5 | CZ6: 4 | DA6: 5 | DB6: 6 | DC6: 4 | DD6: 4 | DE6: 4 | DF6: 6 | DG6: 5 | DH6: 3 | DI6: 4 | DJ6: 2 | DK6: 1 | DL6: 5 | DM6: 2 | DN6: 6 | DO6: 4 | DP6: 2 | DQ6: 4 | DR6: 5 | DS6: =SUM(C6:DR6) -> 416 | DT6: =DS6/120 -> 3.4666667
A7: red | B7: pink | C7: 6 | D7: 1 | E7: 4 | F7: 6 | G7: 6 | H7: 6 | I7: 3 | J7: 7 | K7: 5 | L7: 6 | M7: 6 | N7: 4 | O7: 2 | P7: 7 | Q7: 6 | R7: 7 | S7: 1 | T7: 6 | U7: 4 | V7: 5 | W7: 6 | X7: 4 | Y7: 5 | Z7: 5 | AA7: 7 | AB7: 6 | AC7: 6 | AD7: 2 | AE7: 5 | AF7: 6 | AG7: 5 | AH7: 5 | AI7: 7 | AJ7: 7 | AK7: 5 | AL7: 7 | AM7: 0 | AN7: 4 | AO7: 7 | AP7: 7 | AQ7: 4 | AR7: 7 | AS7: 6 | AT7: 7 | AU7: 5 | AV7: 6 | AW7: 7 | AX7: 7 | AY7: 7 | AZ7: 7 | BA7: 4 | BB7: 5 | BC7: 6 | BD7: 6 | BE7: 6 | BF7: 6 | BG7: 5 | BH7: 6 | BI7: 5 | BJ7: 6 | BK7: 5 | BL7: 5 | BM7: 5 | BN7: 6 | BO7: 4 | BP7: 5 | BQ7: 5 | BR7: 2 | BS7: 1 | BT7: 7 | BU7: 5 | BV7: 3 | BW7: 7 | BX7: 3 | BY7: 4 | BZ7: 1 | CA7: 0 | CB7: 6 | CC7: 5 | CD7: 1 | CE7: 7 | CF7: 5 | CG7: 4 | CH7: 5 | CI7: 5 | CJ7: 6 | CK7: 7 | CL7: 7 | CM7: 7 | CN7: 7 | CO7: 4 | CP7: 6 | CQ7: 7 | CR7: 4 | CS7: 6 | CT7: 5 | CU7: 6 | CV7: 5 | CW7: 5 | CX7: 7 | CY7: 6 | CZ7: 5 | DA7: 7 | DB7: 6 | DC7: 7 | DD7: 7 | DE7: 6 | DF7: 7 | DG7: 5 | DH7: 6 | DI7: 5 | DJ7: 2 | DK7: 7 | DL7: 6 | DM7: 5 | DN7: 1 | DO7: 7 | DP7: 6 | DQ7: 5 | DR7: 6 | DS7: =SUM(C7:DR7) -> 629 | DT7: =DS7/120 -> 5.2416667
A8: envy | B8: joy | C8: 3 | D8: 0 | E8: 0 | F8: 2 | G8: 1 | H8: 0 | I8: 2 | J8: 0 | K8: 1 | L8: 1 | M8: 5 | N8: 0 | O8: 0 | P8: 0 | Q8: 3 | R8: 4 | S8: 0 | T8: 1 | U8: 0 | V8: 3 | W8: 1 | X8: 0 | Y8: 4 | Z8: 0 | AA8: 0 | AB8: 3 | AC8: 2 | AD8: 0 | AE8: 2 | AF8: 6 | AG8: 1 | AH8: 0 | AI8: 6 | AJ8: 5 | AK8: 0 | AL8: 6 | AM8: 0 | AN8: 1 | AO8: 4 | AP8: 1 | AQ8: 1 | AR8: 5 | AS8: 1 | AT8: 5 | AU8: 0 | AV8: 5 | AW8: 3 | AX8: 2 | AY8: 5 | AZ8: 1 | BA8: 1 | BB8: 2 | BC8: 1 | BD8: 1 | BE8: 2 | BF8: 5 | BG8: 0 | BH8: 1 | BI8: 2 | BJ8: 2 | BK8: 1 | BL8: 1 | BM8: 1 | BN8: 1 | BO8: 2 | BP8: 0 | BQ8: 1 | BR8: 0 | BS8: 0 | BT8: 1 | BU8: 0 | BV8: 1 | BW8: 0 | BX8: 0 | BY8: 1 | BZ8: 1 | CA8: 6 | CB8: 1 | CC8: 0 | CD8: 0 | CE8: 7 | CF8: 1 | CG8: 3 | CH8: 1 | CI8: 1 | CJ8: 0 | CK8: 1 | CL8: 1 | CM8: 1 | CN8: 3 | CO8: 2 | CP8: 0 | CQ8: 6 | CR8: 4 | CS8: 1 | CT8: 2 | CU8: 5 | CV8: 3 | CW8: 1 | CX8: 0 | CY8: 0 | CZ8: 0 | DA8: 3 | DB8: 0 | DC8: 2 | DD8: 5 | DE8: 0 | DF8: 0 | DG8: 1 | DH8: 3 | DI8: 3 | DJ8: 0 | DK8: 2 | DL8: 1 | DM8: 2 | DN8: 1 | DO8: 5 | DP8: 1 | DQ8: 0 | DR8: 3 | DS8: =SUM(C8:DR8) -> 206 | DT8: =DS8/120 -> 1.7166667
A9: fear | B9: anger | C9: 6 | D9: 5 | E9: 2 | F9: 5 | G9: 5 | H9: 7 | I9: 4 | J9: 7 | K9: 4 | L9: 6 | M9: 6 | N9: 4 | O9: 1 | P9: 7 | Q9: 4 | R9: 7 | S9: 1 | T9: 5 | U9: 2 | V9: 4 | W9: 6 | X9: 0 | Y9: 4 | Z9: 7 | AA9: 6 | AB9: 5 | AC9: 6 | AD9: 5 | AE9: 6 | AF9: 5 | AG9: 4 | AH9: 1 | AI9: 7 | AJ9: 6 | AK9: 5 | AL9: 7 | AM9: 7 | AN9: 3 | AO9: 6 | AP9: 6 | AQ9: 7 | AR9: 7 | AS9: 5 | AT9: 2 | AU9: 4 | AV9: 5 | AW9: 1 | AX9: 5 | AY9: 6 | AZ9: 5 | BA9: 4 | BB9: 4 | BC9: 6 | BD9: 0 | BE9: 6 | BF9: 6 | BG9: 4 | BH9: 5 | BI9: 5 | BJ9: 5 | BK9: 5 | BL9: 6 | BM9: 6 | BN9: 6 | BO9: 4 | BP9: 6 | BQ9: 2 | BR9: 7 | BS9: 2 | BT9: 5 | BU9: 5 | BV9: 4 | BW9: 4 | BX9: 0 | BY9: 6 | BZ9: 5 | CA9: 6 | CB9: 5 | CC9: 3 | CD9: 5 | CE9: 0 | CF9: 4 | CG9: 6 | CH9: 4 | CI9: 5 | CJ9: 2 | CK9: 5 | CL9: 4 | CM9: 4 | CN9: 6 | CO9: 4 | CP9: 7 | CQ9: 6 | CR9: 5 | CS9: 6 | CT9: 5 | CU9: 5 | CV9: 5 | CW9: 1 | CX9: 7 | CY9: 4 | CZ9: 7 | DA9: 7 | DB9: 6 | DC9: 6 | DD9: 6 | DE9: 4 | DF9: 1 | DG9: 7 | DH9: 0 | DI9: 5 | DJ9: 5 | DK9: 7 | DL9: 2 | DM9: 4 | DN9: 5 | DO9: 4 | DP9: 7 | DQ9: 5 | DR9: 4 | DS9: =SUM(C9:DR9) -> 565 | DT9: =DS9/120 -> 4.7083333
A10: pink | B10: green | C10: 4 | D10: 1 | E10: 1 | F10: 3 | G10: 2 | H10: 1 | I10: 3 | J10: 0 | K10: 1 | L10: 5 | M10: 5 | N10: 4 | O10: 0 | P10: 5 | Q10: 6 | R10: 3 | S10: 4 | T10: 4 | U10: 4 | V10: 3 | W10: 2 | X10: 4 | Y10: 4 | Z10: 3 | AA10: 7 | AB10: 6 | AC10: 3 | AD10: 0 | AE10: 5 | AF10: 6 | AG10: 2 | AH10: 0 | AI10: 7 | AJ10: 6 | AK10: 1 | AL10: 7 | AM10: 0 | AN10: 2 | AO10: 5 | AP10: 4 | AQ10: 2 | AR10: 6 | AS10: 3 | AT10: 6 | AU10: 1 | AV10: 5 | AW10: 2 | AX10: 2 | AY10: 4 | AZ10: 4 | BA10: 3 | BB10: 5 | BC10: 4 | BD10: 2 | BE10: 5 | BF10: 4 | BG10: 2 | BH10: 3 | BI10: 4 | BJ10: 4 | BK10: 1 | BL10: 2 | BM10: 1 | BN10: 0 | BO10: 4 | BP10: 2 | BQ10: 1 | BR10: 1 | BS10: 1 | BT10: 6 | BU10: 2 | BV10: 1 | BW10: 7 | BX10: 0 | BY10: 4 | BZ10: 2 | CA10: 6 | CB10: 1 | CC10: 5 | CD10: 1 | CE10: 7 | CF10: 5 | CG10: 2 | CH10: 1 | CI10: 3 | CJ10: 5 | CK10: 2 | CL10: 5 | CM10: 4 | CN10: 6 | CO10: 2 | CP10: 3 | CQ10: 7 | CR10: 5 | CS10: 4 | CT10: 3 | CU10: 5 | CV10: 5 | CW10: 5 | CX10: 5 | CY10: 2 | CZ10: 3 | DA10: 4 | DB10: 0 | DC10: 6 | DD10: 6 | DE10: 3 | DF10: 4 | DG10: 3 | DH10: 4 | DI10: 2 | DJ10: 2 | DK10: 7 | DL10: 2 | DM10: 4 | DN10: 1 | DO10: 6 | DP10: 5 | DQ10: 4 | DR10: 3 | DS10: =SUM(C10:DR10) -> 407 | DT10: =DS10/120 -> 3.3916667
A11: blue | B11: anger | C11: 2 | D11: 0 | E11: 0 | F11: 4 | G11: 0 | H11: 0 | I11: 2 | J11: 0 | K11: 1 | L11: 1 | M11: 3 | N11: 0 | O11: 0 | P11: 1 | Q11: 1 | R11: 1 | S11: 0 | T11: 1 | U11: 0 | V11: 1 | W11: 3 | X11: 5 | Y11: 4 | Z11: 3 | AA11: 0 | AB11: 1 | AC11: 0 | AD11: 3 | AE11: 4 | AF11: 3 | AG11: 1 | AH11: 0 | AI11: 0 | AJ11: 2 | AK11: 0 | AL11: 2 | AM11: 6 | AN11: 2 | AO11: 0 | AP11: 1 | AQ11: 0 | AR11: 2 | AS11: 0 | AT11: 0 | AU11: 1 | AV11: 0 | AW11: 0 | AX11: 2 | AY11: 5 | AZ11: 2 | BA11: 0 | BB11: 0 | BC11: 3 | BD11: 0 | BE11: 3 | BF11: 1 | BG11: 0 | BH11: 3 | BI11: 1 | BJ11: 1 | BK11: 2 | BL11: 1 | BM11: 3 | BN11: 1 | BO11: 1 | BP11: 0 | BQ11: 1 | BR11: 2 | BS11: 0 | BT11: 5 | BU11: 0 | BV11: 1 | BW11: 0 | BX11: 0 | BY11: 3 | BZ11: 0 | CA11: 0 | CB11: 1 | CC11: 0 | CD11: 1 | CE11: 0 | CF11: 0 | CG11: 0 | CH11: 2 | CI11: 2 | CJ11: 2 | CK11: 5 | CL11: 1 | CM11: 1 | CN11: 1 | CO11: 1 | CP11: 4 | CQ11: 0 | CR11: 1 | CS11: 0 | CT11: 3 | CU11: 2 | CV11: 2 | CW11: 3 | CX11: 2 | CY11: 1 | CZ11: 2 | DA11: 2 | DB11: 0 | DC11: 0 | DD11: 4 | DE11: 1 | DF11: 0 | DG11: 1 | DH11: 0 | DI11: 3 | DJ11: 2 | DK11: 0 | DL11: 1 | DM11: 2 | DN11: 2 | DO11: 3 | DP11: 1 | DQ11: 0 | DR11: 2 | DS11: =SUM(C11:DR11) -> 163 | DT11: =DS11/120 -> 1.3583333
A12: green | B12: joy | C12: 5 | D12: 2 | E12: 4 | F12: 3 | G12: 2 | H12: 6 | I12: 3 | J12: 0 | K12: 5 | L12: 5 | M12: 2 | N12: 4 | O12: 1 | P12: 5 | Q12: 1 | R12: 3 | S12: 1 | T12: 2 | U12: 0 | V12: 0 | W12: 5 | X12: 7 | Y12: 4 | Z12: 4 | AA12: 0 | AB12: 1 | AC12: 1 | AD12: 4 | AE12: 1 | AF12: 1 | AG12: 3 | AH12: 4 | AI12: 1 | AJ12: 2 | AK12: 4 | AL12: 2 | AM12: 5 | AN12: 4 | AO12: 1 | AP12: 6 | AQ12: 5 | AR12: 1 | AS12: 1 | AT12: 0 | AU12: 3 | AV12: 0 | AW12: 1 | AX12: 2 | AY12: 1 | AZ12: 4 | BA12: 1 | BB12: 4 | BC12: 4 | BD12: 6 | BE12: 3 | BF12: 1 | BG12: 3 | BH12: 4 | BI12: 3 | BJ12: 5 | BK12: 3 | BL12: 6 | BM12: 5 | BN12: 4 | BO12: 1 | BP12: 5 | BQ12: 0 | BR12: 2 | BS12: 1 | BT12: 2 | BU12: 4 | BV12: 3 | BW12: 0 | BX12: 4 | BY12: 2 | BZ12: 0 | CA12: 0 | CB12: 1 | CC12: 0 | CD12: 4 | CE12: 0 | CF12: 6 | CG12: 1 | CH12: 4 | CI12: 7 | CJ12: 0 | CK12: 5 | CL12: 0 | CM12: 1 | CN12: 3 | CO12: 1 | CP12: 3 | CQ12: 2 | CR12: 0 | CS12: 0 | CT12: 4 | CU12: 4 | CV12: 3 | CW12: 4 | CX12: 5 | CY12: 5 | CZ12: 5 | DA12: 4 | DB12: 5 | DC12: 3 | DD12: 1 | DE12: 2 | DF12: 4 | DG12: 5 | DH12: 5 | DI12: 4 | DJ12: 0 | DK12: 7 | DL12: 5 | DM12: 1 | DN12: 3 | DO12: 4 | DP12: 1 | DQ12: 3 | DR12: 3 | DS12: =SUM(C12:DR12) -> 336 | DT12: =DS12/120 -> 2.8
A13: anger | B13: defeated | C13: 5 | D13: 5 | E13: 2 | F13: 4 | G13: 4 | H13: 7 | I13: 4 | J13: 1 | K13: 2 | L13: 2 | M13: 5 | N13: 4 | O13: 0 | P13: 7 | Q13: 1 | R13: 4 | S13: 7 | T13: 5 | U13: 2 | V13: 5 | W13: 5 | X13: 6 | Y13: 4 | Z13: 4 | AA13: 2 | AB13: 2 | AC13: 6 | AD13: 4 | AE13: 4 | AF13: 6 | AG13: 6 | AH13: 4 | AI13: 5 | AJ13: 5 | AK13: 5 | AL13: 5 | AM13: 3 | AN13: 3 | AO13: 6 | AP13: 6 | AQ13: 2 | AR13: 6 | AS13: 6 | AT13: 4 | AU13: 6 | AV13: 4 | AW13: 6 | AX13: 5 | AY13: 6 | AZ13: 3 | BA13: 5 | BB13: 5 | BC13: 5 | BD13: 6 | BE13: 2 | BF13: 6 | BG13: 5 | BH13: 4 | BI13: 4 | BJ13: 5 | BK13: 5 | BL13: 6 | BM13: 4 | BN13: 1 | BO13: 3 | BP13: 6 | BQ13: 1 | BR13: 6 | BS13: 5 | BT13: 5 | BU13: 5 | BV13: 3 | BW13: 0 | BX13: 4 | BY13: 4 | BZ13: 1 | CA13: 5 | CB13: 1 | CC13: 0 | CD13: 3 | CE13: 0 | CF13: 0 | CG13: 6 | CH13: 4 | CI13: 6 | CJ13: 3 | CK13: 6 | CL13: 1 | CM13: 4 | CN13: 7 | CO13: 3 | CP13: 4 | CQ13: 5 | CR13: 3 | CS13: 5 | CT13: 5 | CU13: 5 | CV13: 5 | CW13: 2 | CX13: 6 | CY13: 2 | CZ13: 6 | DA13: 5 | DB13: 5 | DC13: 5 | DD13: 4 | DE13: 4 | DF13: 1 | DG13: 6 | DH13: 0 | DI13: 5 | DJ13: 5 | DK13: 1 | DL13: 6 | DM13: 4 | DN13: 5 | DO13: 6 | DP13: 5 | DQ13: 4 | DR13: 4 | DS13: =SUM(C13:DR13) -> 493 | DT13: =DS13/120 -> 4.1083333
... A254: anxiety | B254: boredom | C254: 2 | D254: 4 | E254: 1 | F254: 4 | G254: 1 | H254: 6 | I254: 3 | J254: 5 | K254: 1 | L254: 1 | M254: 5 | N254: 0 | O254: 2 | P254: 2 | Q254: 2 | R254: 2 | S254: 6 | T254: 4 | U254: 1 | V254: 4 | W254: 4 | X254: 6 | Y254: 4 | Z254: 6 | AA254: 0 | AB254: 4 | AC254: 6 | AD254: 0 | AE254: 5 | AF254: 3 | AG254: 6 | AH254: 3 | AI254: 1 | AJ254: 2 | AK254: 3 | AL254: 5 | AM254: 2 | AN254: 2 | AO254: 6 | AP254: 0 | AQ254: 5 | AR254: 5 | AS254: 5 | AT254: 0 | AU254: 0 | AV254: 5 | AW254: 0 | AX254: 2 | AY254: 3 | AZ254: 4 | BA254: 1 | BB254: 4 | BC254: 5 | BD254: 6 | BE254: 1 | BF254: 6 | BG254: 3 | BH254: 4 | BI254: 0 | BJ254: 3 | BK254: 2 | BL254: 1 | BM254: 3 | BN254: 6 | BO254: 2 | BP254: 2 | BQ254: 5 | BR254: 7 | BS254: 5 | BT254: 6 | BU254: 0 | BV254: 0 | BW254: 0 | BX254: 5 | BY254: 3 | BZ254: 3 | CA254: 3 | CB254: 2 | CC254: 0 | CD254: 5 | CE254: 0 | CF254: 5 | CG254: 5 | CH254: 3 | CI254: 2 | CJ254: 0 | CK254: 5 | CL254: 3 | CM254: 2 | CN254: 0 | CO254: 5 | CP254: 0 | CQ254: 6 | CR254: 3 | CS254: 3 | CT254: 1 | CU254: 1 | CV254: 5 | CW254: 7 | CX254: 5 | CY254: 5 | CZ254: 6 | DA254: 3 | DB254: 7 | DC254: 4 | DD254: 4 | DE254: 4 | DF254: 0 | DG254: 6 | DH254: 0 | DI254: 2 | DJ254: 5 | DK254: 4 | DL254: 4 | DM254: 4 | DN254: 3 | DO254: 4 | DP254: 1 | DQ254: 0 | DR254: 2 | DS254: =SUM(C254:DR254) -> 375 | DT254: =DS254/120 -> 3.125

Sheet converted to dissimilarity
A1: BDI | C1: 24 | D1: 11 | E1: 13 | F1: 22 | G1: 11 | H1: 21 | I1: 9 | J1: 5 | K1: 5 | L1: 9 | M1: 20 | N1: 34 | O1: 24 | P1: 0 | Q1: 1 | R1: 10 | S1: 0 | T1: 29 | U1: 0 | V1: 31 | W1: 2 | X1: 1 | Y1: 10 | Z1: 1 | AA1: 0 | AB1: 18 | AC1: 9 | AD1: 29 | AE1: 0 | AF1: 6 | AG1: 29 | AH1: 0 | AI1: 7 | AJ1: 0 | AK1: 0 | AL1: 0 | AM1: 21 | AN1: 21 | AO1: 25 | AP1: 10 | AQ1: 6 | AR1: 34 | AS1: 16 | AT1: 0 | AU1: 19 | AV1: 25 | AW1: 3 | AX1: 28 | AY1: 18 | AZ1: 39 | BA1: 0 | BB1: 25 | BC1: 7 | BD1: 7 | BE1: 12 | BF1: 7 | BG1: 38 | BH1: 3 | BI1: 15 | BJ1: 6 | BK1: 4 | BL1: 7 | BM1: 0 | BN1: 14 | BO1: 3 | BP1: 11 | BQ1: 20 | BR1: 1 | BS1: 8 | BT1: 0 | BU1: 36 | BV1: 18 | BW1: 0 | BX1: 8 | BY1: 10 | BZ1: 11 | CA1: 4 | CB1: 10 | CC1: 5 | CD1: 1 | CE1: 0 | CF1: 12 | CG1: 26 | CH1: 19 | CI1: 0 | CJ1: 1 | CK1: 29 | CL1: 17 | CM1: 1 | CN1: 26 | CO1: 16 | CP1: 12 | CQ1: 13 | CR1: 6 | CS1: 0 | CT1: 10 | CU1: 2 | CV1: 1 | CW1: 0 | CX1: 26 | CY1: 1 | CZ1: 7 | DA1: 4 | DB1: 8 | DC1: 0 | DD1: 4 | DE1: 39 | DF1: 1 | DG1: 17 | DH1: 17 | DI1: 0 | DJ1: 15 | DK1: 9 | DL1: 19 | DM1: 14 | DN1: 5 | DO1: 18 | DP1: 5 | DQ1: 14 | DR1: 32
A2: brown | B2: anger | C2: =7-'converted to 0-7 ALL-value'!C2 -> 7 | D2: =7-'converted to 0-7 ALL-value'!D2 -> 7 | E2: =7-'converted to 0-7 ALL-value'!E2 -> 7 | F2: =7-'converted to 0-7 ALL-value'!F2 -> 1 | G2: =7-'converted to 0-7 ALL-value'!G2 -> 6 | H2: =7-'converted to 0-7 ALL-value'!H2 -> 5 | I2: =7-'converted to 0-7 ALL-value'!I2 -> 6 | J2: =7-'converted to 0-7 ALL-value'!J2 -> 0 | ... DR2: =7-'converted to 0-7 ALL-value'!DR2 -> 5
A3: orange | B3: anxiety | C3: =7-'converted to 0-7 ALL-value'!C3 -> 7 | D3: =7-'converted to 0-7 ALL-value'!D3 -> 7 | E3: =7-'converted to 0-7 ALL-value'!E3 -> 6 | F3: =7-'converted to 0-7 ALL-value'!F3 -> 5 | G3: =7-'converted to 0-7 ALL-value'!G3 -> 7 | H3: =7-'converted to 0-7 ALL-value'!H3 -> 7 | I3: =7-'converted to 0-7 ALL-value'!I3 -> 6 | J3: =7-'converted to 0-7 ALL-value'!J3 -> 7 | ... DR3: =7-'converted to 0-7 ALL-value'!DR3 -> 3
A4: red | B4: yellow | C4: =7-'converted to 0-7 ALL-value'!C4 -> 3 | D4: =7-'converted to 0-7 ALL-value'!D4 -> 6 | E4: =7-'converted to 0-7 ALL-value'!E4 -> 5 | F4: =7-'converted to 0-7 ALL-value'!F4 -> 2 | G4: =7-'converted to 0-7 ALL-value'!G4 -> 3 | H4: =7-'converted to 0-7 ALL-value'!H4 -> 3 | I4: =7-'converted to 0-7 ALL-value'!I4 -> 4 | J4: =7-'converted to 0-7 ALL-value'!J4 -> 0 | ... DR4: =7-'converted to 0-7 ALL-value'!DR4 -> 1
A5: black | B5: blue | C5: =7-'converted to 0-7 ALL-value'!C5 -> 3 | D5: =7-'converted to 0-7 ALL-value'!D5 -> 7 | E5: =7-'converted to 0-7 ALL-value'!E5 -> 6 | F5: =7-'converted to 0-7 ALL-value'!F5 -> 1 | G5: =7-'converted to 0-7 ALL-value'!G5 -> 4 | H5: =7-'converted to 0-7 ALL-value'!H5 -> 1 | I5: =7-'converted to 0-7 ALL-value'!I5 -> 4 | J5: =7-'converted to 0-7 ALL-value'!J5 -> 0 | ... DR5: =7-'converted to 0-7 ALL-value'!DR5 -> 1
A6: green | B6: calm | C6: =7-'converted to 0-7 ALL-value'!C6 -> 2 | D6: =7-'converted to 0-7 ALL-value'!D6 -> 5 | E6: =7-'converted to 0-7 ALL-value'!E6 -> 2 | F6: =7-'converted to 0-7 ALL-value'!F6 -> 2 | G6: =7-'converted to 0-7 ALL-value'!G6 -> 7 | H6: =7-'converted to 0-7 ALL-value'!H6 -> 1 | I6: =7-'converted to 0-7 ALL-value'!I6 -> 4 | J6: =7-'converted to 0-7 ALL-value'!J6 -> 0 | ... DR6: =7-'converted to 0-7 ALL-value'!DR6 -> 2
A7: red | B7: pink | C7: =7-'converted to 0-7 ALL-value'!C7 -> 1 | D7: =7-'converted to 0-7 ALL-value'!D7 -> 6 | E7: =7-'converted to 0-7 ALL-value'!E7 -> 3 | F7: =7-'converted to 0-7 ALL-value'!F7 -> 1 | G7: =7-'converted to 0-7 ALL-value'!G7 -> 1 | H7: =7-'converted to 0-7 ALL-value'!H7 -> 1 | I7: =7-'converted to 0-7 ALL-value'!I7 -> 4 | J7: =7-'converted to 0-7 ALL-value'!J7 -> 0 | ... DR7: =7-'converted to 0-7 ALL-value'!DR7 -> 1
A8: envy | B8: joy | C8: =7-'converted to 0-7 ALL-value'!C8 -> 4 | D8: =7-'converted to 0-7 ALL-value'!D8 -> 7 | E8: =7-'converted to 0-7 ALL-value'!E8 -> 7 | F8: =7-'converted to 0-7 ALL-value'!F8 -> 5 | G8: =7-'converted to 0-7 ALL-value'!G8 -> 6 | H8: =7-'converted to 0-7 ALL-value'!H8 -> 7 | I8: =7-'converted to 0-7 ALL-value'!I8 -> 5 | J8: =7-'converted to 0-7 ALL-value'!J8 -> 7 | ... DR8: =7-'converted to 0-7 ALL-value'!DR8 -> 4
A9: fear | B9: anger | C9: =7-'converted to 0-7 ALL-value'!C9 -> 1 | D9: =7-'converted to 0-7 ALL-value'!D9 -> 2 | E9: =7-'converted to 0-7 ALL-value'!E9 -> 5 | F9: =7-'converted to 0-7 ALL-value'!F9 -> 2 | G9: =7-'converted to 0-7 ALL-value'!G9 -> 2 | H9: =7-'converted to 0-7 ALL-value'!H9 -> 0 | I9: =7-'converted to 0-7 ALL-value'!I9 -> 3 | J9: =7-'converted to 0-7 ALL-value'!J9 -> 0 | ... DR9: =7-'converted to 0-7 ALL-value'!DR9 -> 3
A10: pink | B10: green | C10: =7-'converted to 0-7 ALL-value'!C10 -> 3 | D10: =7-'converted to 0-7 ALL-value'!D10 -> 6 | E10: =7-'converted to 0-7 ALL-value'!E10 -> 6 | F10: =7-'converted to 0-7 ALL-value'!F10 -> 4 | G10: =7-'converted to 0-7 ALL-value'!G10 -> 5 | H10: =7-'converted to 0-7 ALL-value'!H10 -> 6 | I10: =7-'converted to 0-7 ALL-value'!I10 -> 4 | J10: =7-'converted to 0-7 ALL-value'!J10 -> 7 | ... DR10: =7-'converted to 0-7 ALL-value'!DR10 -> 4
A11: blue | B11: anger | C11: =7-'converted to 0-7 ALL-value'!C11 -> 5 | D11: =7-'converted to 0-7 ALL-value'!D11 -> 7 | E11: =7-'converted to 0-7 ALL-value'!E11 -> 7 | F11: =7-'converted to 0-7 ALL-value'!F11 -> 3 | G11: =7-'converted to 0-7 ALL-value'!G11 -> 7 | H11: =7-'converted to 0-7 ALL-value'!H11 -> 7 | I11: =7-'converted to 0-7 ALL-value'!I11 -> 5 | J11: =7-'converted to 0-7 ALL-value'!J11 -> 7 | ... DR11: =7-'converted to 0-7 ALL-value'!DR11 -> 5
A12: green | B12: joy | C12: =7-'converted to 0-7 ALL-value'!C12 -> 2 | D12: =7-'converted to 0-7 ALL-value'!D12 -> 5 | E12: =7-'converted to 0-7 ALL-value'!E12 -> 3 | F12: =7-'converted to 0-7 ALL-value'!F12 -> 4 | G12: =7-'converted to 0-7 ALL-value'!G12 -> 5 | H12: =7-'converted to 0-7 ALL-value'!H12 -> 1 | I12: =7-'converted to 0-7 ALL-value'!I12 -> 4 | J12: =7-'converted to 0-7 ALL-value'!J12 -> 7 | ... DR12: =7-'converted to 0-7 ALL-value'!DR12 -> 4
A13: anger | B13: defeated | C13: =7-'converted to 0-7 ALL-value'!C13 -> 2 | D13: =7-'converted to 0-7 ALL-value'!D13 -> 2 | E13: =7-'converted to 0-7 ALL-value'!E13 -> 5 | F13: =7-'converted to 0-7 ALL-value'!F13 -> 3 | G13: =7-'converted to 0-7 ALL-value'!G13 -> 3 | H13: =7-'converted to 0-7 ALL-value'!H13 -> 0 | I13: =7-'converted to 0-7 ALL-value'!I13 -> 3 | J13: =7-'converted to 0-7 ALL-value'!J13 -> 6 | ... DR13: =7-'converted to 0-7 ALL-value'!DR13 -> 3
... A254: anxiety | B254: boredom | C254: =7-'converted to 0-7 ALL-value'!C254 -> 5 | D254: =7-'converted to 0-7 ALL-value'!D254 -> 3 | E254: =7-'converted to 0-7 ALL-value'!E254 -> 6 | F254: =7-'converted to 0-7 ALL-value'!F254 -> 3 | G254: =7-'converted to 0-7 ALL-value'!G254 -> 6 | H254: =7-'converted to 0-7 ALL-value'!H254 -> 1 | I254: =7-'converted to 0-7 ALL-value'!I254 -> 4 | J254: =7-'converted to 0-7 ALL-value'!J254 -> 2 | ... DR254: =7-'converted to 0-7 ALL-value'!DR254 -> 5

Sheet w.o double
